<?xml version="1.0" ?>
<!-- =================================================================================== -->
<!-- |    This document was autogenerated by xacro from darwin.urdf.xacro              | -->
<!-- =================================================================================== -->
<robot name="darwin">
  <material name="Blue">
    <color rgba="0.0 0.0 0.8 1.0"/>
  </material>
  <material name="Green">
    <color rgba="0.0 0.8 0.0 1.0"/>
  </material>
  <material name="Grey">
    <color rgba="0.3 0.3 0.3 0.8"/>
  </material>
  <material name="Grey2">
    <color rgba="0.9 0.9 0.9 1.0"/>
  </material>
  <material name="Red">
    <color rgba="0.8 0.0 0.0 1.0"/>
  </material>
  <material name="White">
    <color rgba="1.0 1.0 1.0 1.0"/>
  </material>
  <material name="Black">
    <color rgba="0.1 0.1 0.1 1.0"/>
  </material>
  <material name="LightGrey">
    <color rgba="0.6 0.6 0.6 1.0"/>
  </material>
  <!--
        I = m * r^2
      The inertia tensor computed by MeshLab assumes the mass m is equal 
      to the MeshVolume.  We could compute a scaling factor for each part:
        s = ActualMass / MeshVolume
      However, since it is almost the same for all parts, we compute a
      common scaling factor, as: s = Avg(ActualMasses) / Avg(MeshVolumes)
        s = 1.26e-6
      Additionally, distance in MeshLab are in millimeters, so to convert
      r^2 to square meters, we multiply by 0.001^2 = 1e-6
    -->
  <!--
  <property name="MESHVOLUME_DMFB01" value="19027.634766" />
  <property name="MESHVOLUME_DMBB02" value="17309.392578" />
  <property name="MESHVOLUME_DMFB03" value="4172.618164" />
  <property name="MESHVOLUME_DMFB04" value="5622.555664" />
  <property name="MESHVOLUME_DMFB05" value="8814.262695" />
  <property name="MESHVOLUME_DMFB06" value="13174.791992" />
  <property name="MESHVOLUME_DMFB07" value="6234.946777" />
  <property name="MESHVOLUME_DMFF01" value="14216.210938" />
  <property name="MESHVOLUME_SPU5"   value="690.421204" />
  <property name="MESHVOLUME_SPD3B3" value="508.287537" />
  <property name="MESHVOLUME_SPD3B5" value="862.646484" />
  <property name="MESHVOLUME_SPD3B7" value="1217.040894" />
  <property name="MESHVOLUME_SPD4B5" value="1157.969116" />
  <property name="MESHVOLUME_SPD7V4" value="1055.941406" />
  <property name="MESHVOLUME_SPL2B2" value="591.031128" />
  <property name="MESHVOLUME_SPO5"   value="511.205475" />
  <property name="MESHVOLUME_XL320"  value="16403.394531" />
  -->
  <link name="base_link"/>
  <joint name="body_joint" type="fixed">
    <origin rpy="0 0 0" xyz="0 0 0"/>
    <parent link="base_link"/>
    <child link="body_link"/>
  </joint>
  <link name="body_link">
    <visual>
      <origin rpy="0 0 0" xyz="0 0 0"/>
      <geometry>
        <mesh filename="meshes/body.dae" scale="1 1 1"/>
      </geometry>
      <material name="White"/>
    </visual>
    <inertial>
      <origin rpy="0 0 0" xyz="0.0 8.773967e-3 -22.151331e-3"/>
      <mass value="0.021"/>
      <inertia ixx="1.73088082253e-05" ixy="0.0" ixz="0.0" iyy="1.82893689078e-05" iyz="-7.85127962938e-06" izz="1.80141980768e-05"/>
    </inertial>
    <collision>
      <geometry>
        <mesh filename="meshes/body.dae" scale="1 1 1"/>
      </geometry>
    </collision>
  </link>
  <joint name="neck_joint" type="revolute">
    <axis xyz="0 0 1"/>
    <limit effort="0.39" lower="0" upper="5.23598775598" velocity="11.9380520836"/>
    <origin rpy="0 0 -2.61799387799" xyz="-0.009 0 0.063"/>
    <parent link="body_link"/>
    <child link="head_link"/>
  </joint>
  <transmission name="neck_tran">
    <type>transmission_interface/SimpleTransmission</type>
    <joint name="neck_joint">
      <hardwareInterface>EffortJointInterface</hardwareInterface>
    </joint>
    <actuator name="neck_motor">
      <hardwareInterface>EffortJointInterface</hardwareInterface>
      <mechanicalReduction>1</mechanicalReduction>
    </actuator>
  </transmission>
  <link name="head_link">
    <visual>
      <origin rpy="0 0 0" xyz="0 0 0"/> -->
      <geometry>
        <mesh filename="meshes/head.dae" scale="1 1 1"/>
      </geometry>
      <material name="White"/>
    </visual>
    <inertial>
      <origin rpy="0 0 0" xyz="0.000021e-3 14.665582e-3 -8.712881e-3"/>
      <mass value="0.017"/>
      <inertia ixx="7.51745423623e-06" ixy="0.0" ixz="0.0" iyy="8.34919503428e-06" iyz="1.73790355107e-06" izz="8.39632998231e-06"/>
    </inertial>
    <collision>
      <geometry>
        <mesh filename="meshes/head.dae" scale="1 1 1"/>
      </geometry>
    </collision>
  </link>
  <joint name="l_shoulder_joint" type="revolute">
    <axis xyz="0 1 0"/>
    <limit effort="0.39" lower="0" upper="5.23598775598" velocity="11.9380520836"/>
    <origin rpy="0 -2.61799387799 0" xyz="-0.014 0.039 0.042"/>
    <parent link="body_link"/>
    <child link="l_shoulder_link"/>
  </joint>
  <transmission name="l_shoulder_tran">
    <type>transmission_interface/SimpleTransmission</type>
    <joint name="l_shoulder_joint">
      <hardwareInterface>EffortJointInterface</hardwareInterface>
    </joint>
    <actuator name="l_shoulder_motor">
      <hardwareInterface>EffortJointInterface</hardwareInterface>
      <mechanicalReduction>1</mechanicalReduction>
    </actuator>
  </transmission>
  <link name="l_shoulder_link">
    <visual>
      <origin rpy="0 0 0" xyz="0 0 0"/>
      <geometry>
        <mesh filename="meshes/l_shoulder.dae" scale="1 1 1"/>
      </geometry>
      <material name="White"/>
    </visual>
    <inertial>
      <origin rpy="0 0 0" xyz="0.0 -8.846923e-3 7.432426e-3"/>
      <mass value="0.005"/>
      <inertia ixx="5.8934866711e-07" ixy="0.0" ixz="0.0" iyy="1.36828310667e-06" iyz="1.56912529899e-07" izz="1.37156464768e-06"/>
    </inertial>
    <collision>
      <geometry>
        <mesh filename="meshes/l_shoulder.dae" scale="1 1 1"/>
      </geometry>
    </collision>
  </link>
  <joint name="l_biceps_joint" type="revolute">
    <axis xyz="1 0 0"/>
    <limit effort="0.39" lower="0" upper="5.23598775598" velocity="11.9380520836"/>
    <origin rpy="-2.61799387799 0 0" xyz="0 0.018 -0.012"/>
    <parent link="l_shoulder_link"/>
    <child link="l_biceps_link"/>
  </joint>
  <link name="l_biceps_link">
    <visual>
      <origin rpy="0 0 0" xyz="0 0 0"/>
      <geometry>
        <mesh filename="meshes/l_biceps.dae" scale="1 1 1"/>
      </geometry>
      <material name="White"/>
    </visual>
    <inertial>
      <origin rpy="0 0 0" xyz="0.0 -6.745858e-3 0.697233e-3"/>
      <mass value="0.02"/>
      <inertia ixx="2.81694017968e-06" ixy="0.0" ixz="0.0" iyy="1.86878267967e-06" iyz="-9.75527114498e-08" izz="2.44267964483e-06"/>
    </inertial>
    <collision>
      <geometry>
        <mesh filename="meshes/l_biceps.dae" scale="1 1 1"/>
      </geometry>
    </collision>
  </link>
  <transmission name="l_biceps_tran">
    <type>transmission_interface/SimpleTransmission</type>
    <joint name="l_biceps_joint">
      <hardwareInterface>EffortJointInterface</hardwareInterface>
    </joint>
    <actuator name="l_biceps_motor">
      <hardwareInterface>EffortJointInterface</hardwareInterface>
      <mechanicalReduction>1</mechanicalReduction>
    </actuator>
  </transmission>
  <joint name="l_elbow_joint" type="revolute">
    <axis xyz="1 0 0"/>
    <limit effort="0.39" lower="0" upper="5.23598775598" velocity="11.9380520836"/>
    <origin rpy="-2.61799387799 0 0" xyz="0 0 -0.044"/>
    <parent link="l_biceps_link"/>
    <child link="l_hand_link"/>
  </joint>
  <link name="l_hand_link">
    <visual>
      <origin rpy="0 0 0" xyz="0 0 0"/>
      <geometry>
        <mesh filename="meshes/l_hand.dae" scale="1 1 1"/>
      </geometry>
      <material name="White"/>
    </visual>
    <inertial>
      <origin rpy="0 0 0" xyz="0.0 -6.745858e-3 0.697233e-3"/>
      <mass value="0.02"/>
      <inertia ixx="2.81694017968e-06" ixy="0.0" ixz="0.0" iyy="1.86878267967e-06" iyz="-9.75527114498e-08" izz="2.44267964483e-06"/>
    </inertial>
    <collision>
      <geometry>
        <mesh filename="meshes/l_hand.dae" scale="1 1 1"/>
      </geometry>
    </collision>
  </link>
  <joint name="r_shoulder_joint" type="revolute">
    <axis xyz="0 1 0"/>
    <limit effort="0.39" lower="0" upper="5.23598775598" velocity="11.9380520836"/>
    <origin rpy="0 -2.61799387799 0" xyz="-0.014 -0.039 0.042"/>
    <parent link="body_link"/>
    <child link="r_shoulder_link"/>
  </joint>
  <transmission name="r_shoulder_tran">
    <type>transmission_interface/SimpleTransmission</type>
    <joint name="r_shoulder_joint">
      <hardwareInterface>EffortJointInterface</hardwareInterface>
    </joint>
    <actuator name="r_shoulder_motor">
      <hardwareInterface>EffortJointInterface</hardwareInterface>
      <mechanicalReduction>1</mechanicalReduction>
    </actuator>
  </transmission>
  <link name="r_shoulder_link">
    <visual>
      <origin rpy="0 0 0" xyz="0 0 0"/>
      <geometry>
        <mesh filename="meshes/r_shoulder.dae" scale="1 1 1"/>
      </geometry>
      <material name="White"/>
    </visual>
    <inertial>
      <origin rpy="0 0 0" xyz="0.0 -8.846923e-3 7.432426e-3"/>
      <mass value="0.005"/>
      <inertia ixx="5.8934866711e-07" ixy="0.0" ixz="0.0" iyy="1.36828310667e-06" iyz="1.56912529899e-07" izz="1.37156464768e-06"/>
    </inertial>
    <collision>
      <geometry>
        <mesh filename="meshes/r_shoulder.dae" scale="1 1 1"/>
      </geometry>
    </collision>
  </link>
  <joint name="r_biceps_joint" type="revolute">
    <axis xyz="1 0 0"/>
    <limit effort="0.39" lower="0" upper="5.23598775598" velocity="11.9380520836"/>
    <origin rpy="-2.61799387799 0 0" xyz="0 -0.018 -0.012"/>
    <parent link="r_shoulder_link"/>
    <child link="r_biceps_link"/>
  </joint>
  <link name="r_biceps_link">
    <visual>
      <origin rpy="0 0 0" xyz="0 0 0"/>
      <geometry>
        <mesh filename="meshes/r_biceps.dae" scale="1 1 1"/>
      </geometry>
      <material name="White"/>
    </visual>
    <inertial>
      <origin rpy="0 0 0" xyz="0.0 -6.745858e-3 0.697233e-3"/>
      <mass value="0.02"/>
      <inertia ixx="2.81694017968e-06" ixy="0.0" ixz="0.0" iyy="1.86878267967e-06" iyz="-9.75527114498e-08" izz="2.44267964483e-06"/>
    </inertial>
    <collision>
      <geometry>
        <mesh filename="meshes/r_biceps.dae" scale="1 1 1"/>
      </geometry>
    </collision>
  </link>
  <transmission name="r_biceps_tran">
    <type>transmission_interface/SimpleTransmission</type>
    <joint name="r_biceps_joint">
      <hardwareInterface>EffortJointInterface</hardwareInterface>
    </joint>
    <actuator name="r_biceps_motor">
      <hardwareInterface>EffortJointInterface</hardwareInterface>
      <mechanicalReduction>1</mechanicalReduction>
    </actuator>
  </transmission>
  <joint name="r_elbow_joint" type="revolute">
    <axis xyz="1 0 0"/>
    <limit effort="0.39" lower="0" upper="5.23598775598" velocity="11.9380520836"/>
    <origin rpy="-2.61799387799 0 0" xyz="0 0 -0.044"/>
    <parent link="r_biceps_link"/>
    <child link="r_hand_link"/>
  </joint>
  <transmission name="r_elbow_tran">
    <type>transmission_interface/SimpleTransmission</type>
    <joint name="r_elbow_joint">
      <hardwareInterface>EffortJointInterface</hardwareInterface>
    </joint>
    <actuator name="r_elbow_motor">
      <hardwareInterface>EffortJointInterface</hardwareInterface>
      <mechanicalReduction>1</mechanicalReduction>
    </actuator>
  </transmission>
  <link name="r_hand_link">
    <visual>
      <origin rpy="0 0 0" xyz="0 0 0"/>
      <geometry>
        <mesh filename="meshes/r_hand.dae" scale="1 1 1"/>
      </geometry>
      <material name="White"/>
    </visual>
    <inertial>
      <origin rpy="0 0 0" xyz="0.0 -6.745858e-3 0.697233e-3"/>
      <mass value="0.02"/>
      <inertia ixx="2.81694017968e-06" ixy="0.0" ixz="0.0" iyy="1.86878267967e-06" iyz="-9.75527114498e-08" izz="2.44267964483e-06"/>
    </inertial>
    <collision>
      <geometry>
        <mesh filename="meshes/r_hand.dae" scale="1 1 1"/>
      </geometry>
    </collision>
  </link>
  <joint name="l_hip_joint" type="revolute">
    <axis xyz="1 0 0"/>
    <limit effort="0.39" lower="0" upper="5.23598775598" velocity="11.9380520836"/>
    <origin rpy="-2.61799387799 0 0" xyz="-0.024 0.024 -0.03"/>
    <parent link="body_link"/>
    <child link="l_hip_link"/>
  </joint>
  <transmission name="l_hip_tran">
    <type>transmission_interface/SimpleTransmission</type>
    <joint name="l_hip_joint">
      <hardwareInterface>EffortJointInterface</hardwareInterface>
    </joint>
    <actuator name="l_hip_motor">
      <hardwareInterface>EffortJointInterface</hardwareInterface>
      <mechanicalReduction>1</mechanicalReduction>
    </actuator>
  </transmission>
  <link name="l_hip_link">
    <visual>
      <origin rpy="0 0 0" xyz="0 0 0"/>
      <geometry>
        <mesh filename="meshes/l_hip.dae" scale="1 1 1"/>
      </geometry>
      <material name="White"/>
    </visual>
    <inertial>
      <origin rpy="0 0 0" xyz="0.0 -0.147827e-3 0.0"/>
      <mass value="0.001"/>
      <inertia ixx="3.84028571543e-08" ixy="0.0" ixz="0.0" iyy="1.24853845252e-07" iyz="0.0" izz="8.8154566323e-08"/>
    </inertial>
    <collision>
      <geometry>
        <mesh filename="meshes/l_hip.dae" scale="1 1 1"/>
      </geometry>
    </collision>
  </link>
  <joint name="l_thigh_joint" type="revolute">
    <axis xyz="0 1 0"/>
    <limit effort="0.39" lower="0" upper="5.23598775598" velocity="11.9380520836"/>
    <origin rpy="0 -2.61799387799 0" xyz="0.02 0 -0.006"/>
    <parent link="l_hip_link"/>
    <child link="l_thigh_link"/>
  </joint>
  <transmission name="l_thigh_tran">
    <type>transmission_interface/SimpleTransmission</type>
    <joint name="l_thigh_joint">
      <hardwareInterface>EffortJointInterface</hardwareInterface>
    </joint>
    <actuator name="l_thigh_motor">
      <hardwareInterface>EffortJointInterface</hardwareInterface>
      <mechanicalReduction>1</mechanicalReduction>
    </actuator>
  </transmission>
  <link name="l_thigh_link">
    <visual>
      <origin rpy="0 0 0" xyz="0 0 0"/>
      <geometry>
        <mesh filename="meshes/l_thigh.dae" scale="1 1 1"/>
      </geometry>
      <material name="White"/>
    </visual>
    <inertial>
      <origin rpy="0 0 0" xyz="-0.004686e-3 1.501381e-3 -0.004686e-3"/>
      <mass value="0.001"/>
      <inertia ixx="1.51169954143e-08" ixy="-3.79073324689e-12" ixz="1.28661849463e-11" iyy="2.92132536153e-08" iyz="-3.79070922135e-12" izz="1.51169954143e-08"/>
    </inertial>
    <collision>
      <geometry>
        <mesh filename="meshes/l_thigh.dae" scale="1 1 1"/>
      </geometry>
    </collision>
  </link>
  <joint name="l_knee_joint" type="revolute">
    <axis xyz="0 1 0"/>
    <limit effort="0.39" lower="0" upper="5.23598775598" velocity="11.9380520836"/>
    <origin rpy="0 -2.61799387799 0" xyz="0 0 -0.046"/>
    <parent link="l_thigh_link"/>
    <child link="l_lowerleg_link"/>
  </joint>
  <transmission name="l_knee_tran">
    <type>transmission_interface/SimpleTransmission</type>
    <joint name="l_knee_joint">
      <hardwareInterface>EffortJointInterface</hardwareInterface>
    </joint>
    <actuator name="l_knee_motor">
      <hardwareInterface>EffortJointInterface</hardwareInterface>
      <mechanicalReduction>1</mechanicalReduction>
    </actuator>
  </transmission>
  <link name="l_lowerleg_link">
    <visual>
      <origin rpy="0 0 0" xyz="0 0 0"/>
      <geometry>
        <mesh filename="meshes/l_lowerleg.dae" scale="1 1 1"/>
      </geometry>
      <material name="White"/>
    </visual>
    <inertial>
      <origin rpy="0 0 0" xyz="-0.004686e-3 1.501381e-3 -0.004686e-3"/>
      <mass value="0.001"/>
      <inertia ixx="1.51169954143e-08" ixy="-3.79073324689e-12" ixz="1.28661849463e-11" iyy="2.92132536153e-08" iyz="-3.79070922135e-12" izz="1.51169954143e-08"/>
    </inertial>
    <collision>
      <geometry>
        <mesh filename="meshes/l_lowerleg.dae" scale="1 1 1"/>
      </geometry>
    </collision>
  </link>
  <joint name="l_ankle_joint" type="revolute">
    <axis xyz="0 1 0"/>
    <limit effort="0.39" lower="0" upper="5.23598775598" velocity="11.9380520836"/>
    <origin rpy="0 -2.61799387799 0" xyz="0 0 -0.042"/>
    <parent link="l_lowerleg_link"/>
    <child link="l_ankle_link"/>
  </joint>
  <transmission name="l_ankle_tran">
    <type>transmission_interface/SimpleTransmission</type>
    <joint name="l_ankle_joint">
      <hardwareInterface>EffortJointInterface</hardwareInterface>
    </joint>
    <actuator name="l_ankle_motor">
      <hardwareInterface>EffortJointInterface</hardwareInterface>
      <mechanicalReduction>1</mechanicalReduction>
    </actuator>
  </transmission>
  <link name="l_ankle_link">
    <visual>
      <origin rpy="0 0 0" xyz="0 0 0"/>
      <geometry>
        <mesh filename="meshes/l_ankle.dae" scale="1 1 1"/>
      </geometry>
      <material name="White"/>
    </visual>
    <inertial>
      <origin rpy="0 0 0" xyz="0.0 -6.745858e-3 0.697233e-3"/>
      <mass value="0.02"/>
      <inertia ixx="2.81694017968e-06" ixy="0.0" ixz="0.0" iyy="1.86878267967e-06" iyz="-9.75527114498e-08" izz="2.44267964483e-06"/>
    </inertial>
    <collision>
      <geometry>
        <mesh filename="meshes/l_ankle.dae" scale="1 1 1"/>
      </geometry>
    </collision>
  </link>
  <joint name="l_foot_joint" type="revolute">
    <axis xyz="1 0 0"/>
    <limit effort="0.39" lower="0" upper="5.23598775598" velocity="11.9380520836"/>
    <origin rpy="-2.61799387799 0 0" xyz="-0.033 0 0"/>
    <parent link="l_ankle_link"/>
    <child link="l_foot_link"/>
  </joint>
  <transmission name="l_foot_tran">
    <type>transmission_interface/SimpleTransmission</type>
    <joint name="l_foot_joint">
      <hardwareInterface>EffortJointInterface</hardwareInterface>
    </joint>
    <actuator name="l_foot_motor">
      <hardwareInterface>EffortJointInterface</hardwareInterface>
      <mechanicalReduction>1</mechanicalReduction>
    </actuator>
  </transmission>
  <link name="l_foot_link">
    <visual>
      <origin rpy="0 0 0" xyz="0 0 0"/>
      <geometry>
        <mesh filename="meshes/l_foot.dae" scale="1 1 1"/>
      </geometry>
      <material name="White"/>
    </visual>
    <inertial>
      <origin rpy="0 0 0" xyz="-0.000081e-3 10.773119e-3 17.660477e-3"/>
      <mass value="0.016"/>
      <inertia ixx="1.39605976043e-05" ixy="-9.94118800416e-12" ixz="-4.31923961305e-11" iyy="1.64605878036e-05" iyz="1.89368309696e-06" izz="4.50497524531e-06"/>
    </inertial>
    <collision>
      <geometry>
        <mesh filename="meshes/l_foot.dae" scale="1 1 1"/>
      </geometry>
    </collision>
  </link>
  <joint name="r_hip_joint" type="revolute">
    <axis xyz="1 0 0"/>
    <limit effort="0.39" lower="0" upper="5.23598775598" velocity="11.9380520836"/>
    <origin rpy="-2.61799387799 0 0" xyz="-0.024 -0.024 -0.03"/>
    <parent link="body_link"/>
    <child link="r_hip_link"/>
  </joint>
  <transmission name="r_hip_tran">
    <type>transmission_interface/SimpleTransmission</type>
    <joint name="r_hip_joint">
      <hardwareInterface>EffortJointInterface</hardwareInterface>
    </joint>
    <actuator name="r_hip_motor">
      <hardwareInterface>EffortJointInterface</hardwareInterface>
      <mechanicalReduction>1</mechanicalReduction>
    </actuator>
  </transmission>
  <link name="r_hip_link">
    <visual>
      <origin rpy="0 0 0" xyz="0 0 0"/>
      <geometry>
        <mesh filename="meshes/r_hip.dae" scale="1 1 1"/>
      </geometry>
      <material name="White"/>
    </visual>
    <inertial>
      <origin rpy="0 0 0" xyz="0.0 -0.147827e-3 0.0"/>
      <mass value="0.001"/>
      <inertia ixx="3.84028571543e-08" ixy="0.0" ixz="0.0" iyy="1.24853845252e-07" iyz="0.0" izz="8.8154566323e-08"/>
    </inertial>
    <collision>
      <geometry>
        <mesh filename="meshes/r_hip.dae" scale="1 1 1"/>
      </geometry>
    </collision>
  </link>
  <joint name="r_thigh_joint" type="revolute">
    <axis xyz="0 1 0"/>
    <limit effort="0.39" lower="0" upper="5.23598775598" velocity="11.9380520836"/>
    <origin rpy="0 -2.61799387799 0" xyz="0.02 0 -0.006"/>
    <parent link="r_hip_link"/>
    <child link="r_thigh_link"/>
  </joint>
  <transmission name="r_thigh_tran">
    <type>transmission_interface/SimpleTransmission</type>
    <joint name="r_thigh_joint">
      <hardwareInterface>EffortJointInterface</hardwareInterface>
    </joint>
    <actuator name="r_thigh_motor">
      <hardwareInterface>EffortJointInterface</hardwareInterface>
      <mechanicalReduction>1</mechanicalReduction>
    </actuator>
  </transmission>
  <link name="r_thigh_link">
    <visual>
      <origin rpy="0 0 0" xyz="0 0 0"/>
      <geometry>
        <mesh filename="meshes/r_thigh.dae" scale="1 1 1"/>
      </geometry>
      <material name="White"/>
    </visual>
    <inertial>
      <origin rpy="0 0 0" xyz="-0.004686e-3 1.501381e-3 -0.004686e-3"/>
      <mass value="0.001"/>
      <inertia ixx="1.51169954143e-08" ixy="-3.79073324689e-12" ixz="1.28661849463e-11" iyy="2.92132536153e-08" iyz="-3.79070922135e-12" izz="1.51169954143e-08"/>
    </inertial>
    <collision>
      <geometry>
        <mesh filename="meshes/r_thigh.dae" scale="1 1 1"/>
      </geometry>
    </collision>
  </link>
  <joint name="r_knee_joint" type="revolute">
    <axis xyz="0 1 0"/>
    <limit effort="0.39" lower="0" upper="5.23598775598" velocity="11.9380520836"/>
    <origin rpy="0 -2.61799387799 0" xyz="0 0 -0.046"/>
    <parent link="r_thigh_link"/>
    <child link="r_lowerleg_link"/>
  </joint>
  <transmission name="r_knee_tran">
    <type>transmission_interface/SimpleTransmission</type>
    <joint name="r_knee_joint">
      <hardwareInterface>EffortJointInterface</hardwareInterface>
    </joint>
    <actuator name="r_knee_motor">
      <hardwareInterface>EffortJointInterface</hardwareInterface>
      <mechanicalReduction>1</mechanicalReduction>
    </actuator>
  </transmission>
  <link name="r_lowerleg_link">
    <visual>
      <origin rpy="0 0 0" xyz="0 0 0"/>
      <geometry>
        <mesh filename="meshes/r_lowerleg.dae" scale="1 1 1"/>
      </geometry>
      <material name="White"/>
    </visual>
    <inertial>
      <origin rpy="0 0 0" xyz="-0.004686e-3 1.501381e-3 -0.004686e-3"/>
      <mass value="0.001"/>
      <inertia ixx="1.51169954143e-08" ixy="-3.79073324689e-12" ixz="1.28661849463e-11" iyy="2.92132536153e-08" iyz="-3.79070922135e-12" izz="1.51169954143e-08"/>
    </inertial>
    <collision>
      <geometry>
        <mesh filename="meshes/r_lowerleg.dae" scale="1 1 1"/>
      </geometry>
    </collision>
  </link>
  <joint name="r_ankle_joint" type="revolute">
    <axis xyz="0 1 0"/>
    <limit effort="0.39" lower="0" upper="5.23598775598" velocity="11.9380520836"/>
    <origin rpy="0 -2.61799387799 0" xyz="0 0 -0.042"/>
    <parent link="r_lowerleg_link"/>
    <child link="r_ankle_link"/>
  </joint>
  <transmission name="r_ankle_tran">
    <type>transmission_interface/SimpleTransmission</type>
    <joint name="r_ankle_joint">
      <hardwareInterface>EffortJointInterface</hardwareInterface>
    </joint>
    <actuator name="r_ankle_motor">
      <hardwareInterface>EffortJointInterface</hardwareInterface>
      <mechanicalReduction>1</mechanicalReduction>
    </actuator>
  </transmission>
  <link name="r_ankle_link">
    <visual>
      <origin rpy="0 0 0" xyz="0 0 0"/>
      <geometry>
        <mesh filename="meshes/r_ankle.dae" scale="1 1 1"/>
      </geometry>
      <material name="White"/>
    </visual>
    <inertial>
      <origin rpy="0 0 0" xyz="0.0 -6.745858e-3 0.697233e-3"/>
      <mass value="0.02"/>
      <inertia ixx="2.81694017968e-06" ixy="0.0" ixz="0.0" iyy="1.86878267967e-06" iyz="-9.75527114498e-08" izz="2.44267964483e-06"/>
    </inertial>
    <collision>
      <geometry>
        <mesh filename="meshes/r_ankle.dae" scale="1 1 1"/>
      </geometry>
    </collision>
  </link>
  <joint name="r_foot_joint" type="revolute">
    <axis xyz="1 0 0"/>
    <limit effort="0.39" lower="0" upper="5.23598775598" velocity="11.9380520836"/>
    <origin rpy="-2.61799387799 0 0" xyz="-0.033 0 0"/>
    <parent link="r_ankle_link"/>
    <child link="r_foot_link"/>
  </joint>
  <transmission name="r_foot_tran">
    <type>transmission_interface/SimpleTransmission</type>
    <joint name="r_foot_joint">
      <hardwareInterface>EffortJointInterface</hardwareInterface>
    </joint>
    <actuator name="r_foot_motor">
      <hardwareInterface>EffortJointInterface</hardwareInterface>
      <mechanicalReduction>1</mechanicalReduction>
    </actuator>
  </transmission>
  <link name="r_foot_link">
    <visual>
      <origin rpy="0 0 0" xyz="0 0 0"/>
      <geometry>
        <mesh filename="meshes/r_foot.dae" scale="1 1 1"/>
      </geometry>
      <material name="White"/>
    </visual>
    <inertial>
      <origin rpy="0 0 0" xyz="-0.000081e-3 10.773119e-3 17.660477e-3"/>
      <mass value="0.016"/>
      <inertia ixx="1.39605976043e-05" ixy="-9.94118800416e-12" ixz="-4.31923961305e-11" iyy="1.64605878036e-05" iyz="1.89368309696e-06" izz="4.50497524531e-06"/>
    </inertial>
    <collision>
      <geometry>
        <mesh filename="meshes/r_foot.dae" scale="1 1 1"/>
      </geometry>
    </collision>
  </link>
</robot>

