<?xml version="1.0"?>
<robot xmlns:sensor="http://playerstage.sourceforge.net/gazebo/xmlschema/#sensor"
       xmlns:controller="http://playerstage.sourceforge.net/gazebo/xmlschema/#controller"
       xmlns:interface="http://playerstage.sourceforge.net/gazebo/xmlschema/#interface"
       xmlns:xacro="http://ros.org/wiki/xacro">

  <property name="M_PI" value="3.1415926535897931" />
  <property name="XL320_MAX_TORQUE" value="0.39" />
  <property name="XL320_MAX_VELOCITY" value="${114 * 2*M_PI / 60}" />
  <property name="XL320_DAMPING" value="0.7" />

  <xacro:macro name="darwin_transmission" params="name">
    <transmission name="${name}_tran">
      <type>transmission_interface/SimpleTransmission</type>
      <joint name="${name}_joint">
        <hardwareInterface>EffortJointInterface</hardwareInterface>
      </joint>
      <actuator name="${name}_motor">
        <hardwareInterface>EffortJointInterface</hardwareInterface>
        <mechanicalReduction>1</mechanicalReduction>
      </actuator>
    </transmission>
  </xacro:macro>

  <xacro:macro name="darwin_servo_fixed" params="name parent xyz rpy">
    <joint name="${name}_servo_joint" type="fixed">
      <origin xyz="${xyz}" rpy="${rpy}" />
      <parent link="${parent}"/>
      <child link="${name}_servo_link"/>
    </joint>
    <xacro:darwin_xl320 name="${name}_servo" />
    <joint name="${name}_joint" type="revolute">
      <axis xyz="0 0 1" />
      <limit lower="0" upper="${300*M_PI/180}" effort="${XL320_MAX_TORQUE}" velocity="${XL320_MAX_VELOCITY}" />
      <origin xyz="0 0 0" rpy="0 0 ${-150*M_PI/180}" />
      <parent link="${name}_servo_link"/>
      <child link="${name}_link"/>
      <!--
      <dynamics damping="${XL320_DAMPING}" />
      -->
    </joint>
    <link name="${name}_link">
      <inertial>
        <mass value="0.0001" />
        <inertia ixx="1.0e-12" ixy="0.0" ixz="0.0" iyy="1.0e-12" iyz="0.0" izz="1.0e-12"/>
      </inertial>
    </link>
    <xacro:darwin_transmission name="${name}" />
  </xacro:macro>
  
  <xacro:macro name="darwin_servo_rotating" params="name parent xyz rpy">
    <joint name="${name}_axis_joint" type="fixed">
      <origin xyz="${xyz}" rpy="${rpy}" />
      <parent link="${parent}"/>
      <child link="${name}_axis_link"/>
    </joint>
    <link name="${name}_axis_link">
      <inertial>
        <mass value="0.0001" />
        <inertia ixx="1.0e-12" ixy="0.0" ixz="0.0" iyy="1.0e-12" iyz="0.0" izz="1.0e-12"/>
      </inertial>
    </link>
    <joint name="${name}_joint" type="revolute">
      <axis xyz="0 0 1" />
      <limit lower="0" upper="${300*M_PI/180}" effort="${XL320_MAX_TORQUE}" velocity="${XL320_MAX_VELOCITY}" />
      <origin xyz="0 0 0" rpy="0 0 ${-150*M_PI/180}" />
      <parent link="${name}_axis_link"/>
      <child link="${name}_link"/>
      <!--
      <dynamics damping="${XL320_DAMPING}" />
      -->
    </joint>
    <xacro:darwin_xl320 name="${name}" />
    <xacro:darwin_transmission name="${name}" />
  </xacro:macro>
  
  <xacro:macro name="darwin_servo_wheel" params="name">
    <xacro:darwin_spo5 name="${name}_spo" parent="${name}_link" xyz="0 0 -0.015" rpy="${M_PI/2} 0 0" />
  </xacro:macro>
  
  <xacro:macro name="darwin_servo_fixed_with_wheel" params="name parent xyz rpy">
    <xacro:darwin_servo_fixed name="${name}" parent="${parent}" xyz="${xyz}" rpy="${rpy}" />
    <xacro:darwin_servo_wheel name="${name}" />
  </xacro:macro>
  
  <xacro:macro name="darwin_servo_rotating_with_wheel" params="name parent xyz rpy">
    <xacro:darwin_servo_rotating name="${name}" parent="${parent}" xyz="${xyz}" rpy="${rpy}" />
    <xacro:darwin_servo_wheel name="${name}" />
  </xacro:macro>

</robot>
